#VRML_SIM R2023b utf8

EXTERNPROTO "https://raw.githubusercontent.com/cyberbotics/webots/23928ebf69af2e5cafa3ca7b9acc8271593948ca/projects/objects/backgrounds/protos/TexturedBackground.proto"
EXTERNPROTO "https://raw.githubusercontent.com/cyberbotics/webots/23928ebf69af2e5cafa3ca7b9acc8271593948ca/projects/objects/backgrounds/protos/TexturedBackgroundLight.proto"
EXTERNPROTO "https://raw.githubusercontent.com/cyberbotics/webots/R2023b/projects/appearances/protos/GlossyPaint.proto"
EXTERNPROTO "https://raw.githubusercontent.com/cyberbotics/webots/R2023b/projects/appearances/protos/MattePaint.proto"
EXTERNPROTO "https://raw.githubusercontent.com/cyberbotics/webots/R2023b/projects/appearances/protos/TireRubber.proto"
EXTERNPROTO "https://raw.githubusercontent.com/cyberbotics/webots/R2023b/projects/objects/floors/protos/CircleArena.proto"

WorldInfo {
}
Viewpoint {
  orientation -0.2566168076856191 0.3351025341032018 0.9065616943434431 1.393004866057903
  position -1.8521915886427953 -6.618952139938136 4.276616381058339
}
TexturedBackground {
}
TexturedBackgroundLight {
}
CircleArena {
  radius 3
  floorAppearance MattePaint {
  }
}
Shape {
  appearance MattePaint {
    baseColor 0 0 0
  }
  geometry Cylinder {
    height 0.01
    radius 2
  }
}
Robot {
  translation -0.04 0 0.11
  rotation 0 0 1 1.5708
  children [
    RangeFinder {
      translation 0.1 0 0.02
      children [
        Shape {
          appearance GlossyPaint {
            baseColor 1 0 0
          }
          geometry Box {
            size 0.01 0.01 0.01
          }
        }
      ]
      name "Rangefinder1"
    }
    Camera {
      translation 0.1 0 0.03
      children [
        Shape {
          appearance MattePaint {
            baseColor 0 1 0
          }
          geometry Cylinder {
            height 0.01
            radius 0.005
          }
        }
      ]
      name "Camara1"
      recognition Recognition {
      }
    }
    DistanceSensor {
      translation 0.08 0.05 0.02
      rotation 0 0 1 1.5708
      children [
        DEF SensorDist Shape {
          appearance MattePaint {
            baseColor 0 0 1
          }
          geometry Box {
            size 0.01 0.01 0.01
          }
        }
      ]
      name "SensorDistIzq"
    }
    DistanceSensor {
      translation 0.08 -0.04 0.02
      rotation 0 0 1 -1.5707953071795862
      children [
        DEF SensorDist Shape {
          appearance MattePaint {
            baseColor 0 0 1
          }
          geometry Box {
            size 0.01 0.01 0.01
          }
        }
      ]
      name "SensorDistDer"
    }
    DEF Cuerpo Shape {
      appearance MattePaint {
        baseColor 0.5 0.5 1
      }
      geometry Box {
        size 0.2 0.1 0.02
      }
    }
    DEF RuedaDer HingeJoint {
      jointParameters HingeJointParameters {
      }
      device [
        PositionSensor {
          name "PosSensorRD"
        }
        DEF MotorD RotationalMotor {
        }
      ]
      endPoint Solid {
        translation -0.05 -0.06 3.05886e-08
        rotation -0.9999999999999999 0 0 1.5707953071795862
        children [
          DEF Rueda Shape {
            appearance TireRubber {
            }
            geometry Cylinder {
              height 0.015
              radius 0.03
            }
          }
        ]
        name "SolidRuedaDer"
        boundingObject USE Rueda
        physics DEF PhysicsRueda Physics {
          density -1
          mass 0.5
        }
      }
    }
    DEF RuedaDerF HingeJoint {
      jointParameters HingeJointParameters {
      }
      device [
        PositionSensor {
          name "PosSensorRD"
        }
        DEF MotorD RotationalMotor {
        }
      ]
      endPoint Solid {
        translation 0.06 -0.06 3.05886e-08
        rotation -0.9999999999999999 0 0 1.5707953071795862
        children [
          DEF Rueda Shape {
            appearance TireRubber {
            }
            geometry Cylinder {
              height 0.015
              radius 0.03
            }
          }
        ]
        name "SolidRuedaDer(1)"
        boundingObject USE Rueda
        physics DEF PhysicsRueda Physics {
          density -1
          mass 0.5
        }
      }
    }
    DEF RuedaIzq HingeJoint {
      jointParameters HingeJointParameters {
      }
      device [
        PositionSensor {
          name "PosSensorRI"
        }
        DEF MotorI RotationalMotor {
        }
      ]
      endPoint Solid {
        translation -0.05 0.06 4.67978e-08
        rotation 1 0 0 1.5708
        children [
          DEF Rueda Shape {
            appearance TireRubber {
            }
            geometry Cylinder {
              height 0.015
              radius 0.03
            }
          }
        ]
        name "SolidRuedaIzq"
        boundingObject USE Rueda
        physics DEF PhysicsRueda Physics {
          density -1
          mass 0.5
        }
      }
    }
    DEF RuedaIzqF HingeJoint {
      jointParameters HingeJointParameters {
      }
      device [
        PositionSensor {
          name "PosSensorRI"
        }
        DEF MotorI RotationalMotor {
        }
      ]
      endPoint Solid {
        translation 0.06 0.06 4.67978e-08
        rotation 1 0 0 1.5708
        children [
          DEF Rueda Shape {
            appearance TireRubber {
            }
            geometry Cylinder {
              height 0.015
              radius 0.03
            }
          }
        ]
        name "SolidRuedaIzq(1)"
        boundingObject USE Rueda
        physics DEF PhysicsRueda Physics {
          density -1
          mass 0.5
        }
      }
    }
    DEF Ruedita Solid {
    }
  ]
  boundingObject USE Cuerpo
  physics Physics {
    density -1
    mass 3
    centerOfMass [
      0 0 0
    ]
  }
}
